use anyhow::Result;
use shotover_proxy::runner::{ConfigOpts, Runner};
use std::sync::mpsc;
use tokio::runtime::{Handle as RuntimeHandle, Runtime};
use tokio::sync::watch;
use tokio::task::JoinHandle;

#[must_use]
pub struct ShotoverManager {
    pub runtime: Option<Runtime>,
    pub runtime_handle: RuntimeHandle,
    pub join_handle: Option<JoinHandle<Result<()>>>,
    pub trigger_shutdown_tx: watch::Sender<bool>,
    panic_occured_rx: mpsc::Receiver<()>,
}

// false unused warnings caused by https://github.com/rust-lang/rust/issues/46379
impl ShotoverManager {
    #[allow(dead_code)]
    pub fn from_topology_file(topology_path: &str) -> ShotoverManager {
        ShotoverManager::from_topology_file_inner(topology_path, true)
    }

    #[allow(dead_code)]
    pub fn from_topology_file_without_observability(topology_path: &str) -> ShotoverManager {
        ShotoverManager::from_topology_file_inner(topology_path, false)
    }

    fn from_topology_file_inner(topology_path: &str, observability: bool) -> ShotoverManager {
        // std does not yet support doing this without a race condition.
        // See: https://github.com/rust-lang/rust/issues/92649
        let prev_hook = std::panic::take_hook();
        let (tx, panic_occured_rx) = mpsc::sync_channel(10);
        std::panic::set_hook(Box::new(move |panic_info| {
            // This panic hook will outlive the Receiver.
            // so we should just ignore failures to send as that is expected once the Receiver drops.
            let _ = tx.try_send(());

            prev_hook(panic_info)
        }));

        let opts = ConfigOpts {
            topology_file: topology_path.into(),
            config_file: "tests/helpers/config.yaml".into(),
            ..ConfigOpts::default()
        };
        let spawn = if observability {
            Runner::new(opts)
                .unwrap_or_else(|x| panic!("{x} occurred processing {topology_path:?}"))
                .with_observability_interface()
                .unwrap_or_else(|x| panic!("{x} occurred processing {topology_path:?}"))
                .run_spawn()
        } else {
            Runner::new(opts)
                .unwrap_or_else(|x| panic!("{x} occurred processing {topology_path:?}"))
                .run_spawn()
        };

        // If we allow the tracing_guard to be dropped then the following tests in the same file will not get tracing so we mem::forget it.
        // This is because tracing can only be initialized once in the same execution, secondary attempts to initalize tracing will silently fail.
        std::mem::forget(spawn.tracing_guard);

        ShotoverManager {
            runtime: spawn.runtime,
            runtime_handle: spawn.runtime_handle,
            join_handle: Some(spawn.join_handle),
            trigger_shutdown_tx: spawn.trigger_shutdown_tx,
            panic_occured_rx,
        }
    }

    fn shutdown_shotover(&mut self) -> Result<()> {
        self.trigger_shutdown_tx.send(true)?;
        let _enter_guard = self.runtime_handle.enter();
        futures::executor::block_on(self.join_handle.take().unwrap())?
    }
}

impl Drop for ShotoverManager {
    fn drop(&mut self) {
        // Must clear the recorder before skipping a shutdown on panic; if one test panics and the recorder is not cleared,
        // the following tests will panic because they will try to set another recorder
        // TODO: This is unsafe due to a possible race condition and we are doing nothing to prevent that race condition.
        // It is left as is because there are no reasonable solutions to this problem at the moment.
        // A possible way to trigger this issue would be creating a ShotoverManager instance in one thread while dropping a ShotoverManager instance in another thread.
        unsafe { metrics::clear_recorder() };

        if std::thread::panicking() {
            // If already panicking do not panic while attempting to shutdown shotover in order to avoid a double panic.
            if let Err(err) = self.shutdown_shotover() {
                println!("Failed to shutdown shotover: {err}")
            }
        } else {
            self.shutdown_shotover().unwrap();

            // When a panic occurs in a shotover tokio task that isnt joined on, tokio will catch the panic, print the panic message and shotover will continue running happily.
            // This behaviour is reasonable and makes shotover more robust but in our integration tests we want to ensure that panics never ever occur.
            // As a result we need the following assertion to detect panics that occur within tasks.
            if let Ok(()) = self.panic_occured_rx.try_recv() {
                panic!("Panic occured within a shotover task during integration test.\nPlease refer to the panic message that should have been already been logged to stdout by tokio when the panic occured.")
            }
        }
    }
}
